<?xml version="1.0" encoding="UTF-8"?>
<!-- Generated by org.testng.reporters.JUnitReportReporter -->
<testsuite hostname="LGB03000619" failures="1" tests="2" name="selenium_tests.Runner" time="27.703" errors="0" timestamp="12 Jul 2022 07:43:24 GMT" skipped="1">
  <testcase classname="selenium_tests.Runner" name="run_scenario" time="10.614">
    <failure message="expected [4] but found [0]" type="java.lang.AssertionError">
      <![CDATA[java.lang.AssertionError: expected [4] but found [0]
	at org.testng.Assert.fail(Assert.java:93)
	at org.testng.Assert.failNotEquals(Assert.java:512)
	at org.testng.Assert.assertEqualsImpl(Assert.java:134)
	at org.testng.Assert.assertEquals(Assert.java:115)
	at org.testng.Assert.assertEquals(Assert.java:388)
	at org.testng.Assert.assertEquals(Assert.java:398)
	at selenium_tests.feature_steps.addtocart_feature.he_see_items_in_the_cart(addtocart_feature.java:57)
	at âœ½.he see 4 items in the cart(src/test/resources/Features/AddtoCart.feature:9)
]]>
    </failure>
  </testcase> <!-- run_scenario -->
  <testcase classname="selenium_tests.Runner" name="run_scenario" time="17.089">
    <skipped/>
  </testcase> <!-- run_scenario -->
</testsuite> <!-- selenium_tests.Runner -->
